<?xml version="1.0"?>
<robot xmlns:xacro="http://www.ros.org/wiki/xacro" name="xy_plotter">

  <!-- Base Frame - Hollow Square -->
  <link name="boundary_link">
    <inertial>
      <mass value="10" />
      <inertia ixx="0.4" ixy="0.0" ixz="0.0" iyy="0.4" iyz="0.0" izz="0.2"/>
    </inertial>

    <!-- Front Boundary -->
    <visual>
      <origin xyz="0.0 0.30 0.0" rpy="0 0 0"/>
      <geometry>
        <box size="0.55 0.05 0.05"/>  
      </geometry>
      <material name="grey">
        <color rgba="0.5 0.5 0.5 1"/>
      </material>
    </visual>

    <!-- Back Boundary -->
    <visual>
      <origin xyz="0.0 -0.30 0.0" rpy="0 0 0"/>
      <geometry>
        <box size="0.55 0.05 0.05"/>
      </geometry>
      <material name="grey">
        <color rgba="0.5 0.5 0.5 1"/>
      </material>
    </visual>

    <!-- Left Boundary -->
    <visual>
      <origin xyz="-0.30 0.0 0.0" rpy="0 0 0"/>
      <geometry>
        <box size="0.05 0.65 0.05"/>  
      </geometry>
      <material name="grey">
        <color rgba="0.5 0.5 0.5 1"/>
      </material>
    </visual>

    <!-- Right Boundary -->
    <visual>
      <origin xyz="0.30 0.0 0.0" rpy="0 0 0"/>
      <geometry>
        <box size="0.05 0.65 0.05"/>
      </geometry>
      <material name="grey">
        <color rgba="0.5 0.5 0.5 1"/>
      </material>
    </visual>

    <!-- Add collision -->
    <!-- <collision>
      <origin xyz="0.0 0.30 0.0"/>
      <geometry>
        <box size="0.55 0.05 0.05"/>
      </geometry>
    </collision>

    <collision>
      <origin xyz="0.0 -0.30 0.0"/>
      <geometry>
        <box size="0.55 0.05 0.05"/>
      </geometry>
    </collision>

    <collision>
      <origin xyz="-0.30 0.0 0.0"/>
      <geometry>
        <box size="0.05 0.65 0.05"/>
      </geometry>
    </collision>

    <collision>
      <origin xyz="0.30 0.0 0.0"/>
      <geometry>
        <box size="0.05 0.65 0.05"/>
      </geometry>
    </collision> -->
  </link>

  <!-- Gazebo material for boundary_link -->
  <gazebo reference="boundary_link">
    <material>Gazebo/Grey</material>
  </gazebo>

  <joint name="connect_world_and_boundary_link" type="fixed">
    <child link="boundary_link"/>
    <parent link="world"/>
    <origin rpy="0 0 0" xyz="-0.9 0.7 0.95"/>
  </joint>

  <!-- Link #2 (Slider Link) -->
  <link name="slider_link">
    <inertial>
        <mass value="0.18" />
        <inertia ixx="0.0002835" ixy="0.0" ixz="0.0" iyy="0.0002835" iyz="0.0" izz="0.000324" />
    </inertial>
    <!-- <collision>
      <geometry>
        <box size="0.001 0.001 0.001" />
      </geometry>
    </collision> -->
    <visual>
      <geometry>
        <box size="0.001 0.001 0.001" />
      </geometry>
      <material name="red">
        <color rgba="1 0 0 1"/>
      </material>
    </visual>
  </link>

  <!-- Link #3 (Slider Link) -->
  <link name="second_link">
    <inertial>
        <mass value="0.18" />
        <inertia ixx="0.0002835" ixy="0.0" ixz="0.0" iyy="0.0002835" iyz="0.0" izz="0.000324" />
    </inertial>
    <!-- <collision>
      <geometry>
        <box size="0.001 0.001 0.001" />
      </geometry>
    </collision> -->
    <visual>
      <geometry>
        <box size="0.001 0.001 0.001" />
      </geometry>
      <material name="green">
        <color rgba="0 1 0 1"/>
      </material>
    </visual>
  </link>

  <!-- Link #4 (Plate) -->
  <link name="plate_link">
    <inertial>
        <mass value="0.5" />
        <inertia ixx="0.01" ixy="0.0" ixz="0.0" iyy="0.01" iyz="0.0" izz="0.01"/>
    </inertial>
    <!-- <collision>
      <geometry>
        <box size="0.2 0.2 0.02" />  
      </geometry>
    </collision> -->
    <visual>
      <geometry>
        <box size="0.2 0.2 0.02" />
      </geometry>
      <material name="gray">
        <color rgba="0.5 0.5 0.5 1"/>
      </material>
    </visual>
  </link>

  <!-- Joint for X-axis (Base to Slider) -->
  <joint name="base_to_slider_joint" type="prismatic">
    <parent link="boundary_link"/>
    <child link="slider_link"/>
    <axis xyz="1 0 0"/>
    <origin xyz="0.0 0.0 0.025" rpy="0.0 0.0 0.0"/>
    <limit lower="-0.25" upper="0.25" effort="100.0" velocity="1.0"/>
  </joint>

  <!-- Joint for Y-axis (Slider to Second Link) -->
  <joint name="slider_to_second_joint" type="prismatic">
    <parent link="slider_link"/>
    <child link="second_link"/>
    <axis xyz="0 1 0"/>
    <origin xyz="0.0 0.0 0" rpy="0.0 0.0 0.0"/>
    <limit lower="-0.25" upper="0.25" effort="100.0" velocity="1.0"/>
  </joint>

  <!-- Fixed Joint: Attach Plate to Second Link -->
  <joint name="second_to_plate_joint" type="fixed">
    <parent link="second_link"/>
    <child link="plate_link"/>
    <origin xyz="0.0 0.0 0.0" rpy="0.0 0.0 0.0"/>  <!-- Plate positioned slightly above the second link -->
  </joint>

  <!-- Gazebo ROS Control Plugin -->
  <gazebo>
    <plugin name="gazebo_ros_control" filename="libgazebo_ros_control.so">
      <robotNamespace>/xy_plotter</robotNamespace>
      <robotSimType>gazebo_ros_control/DefaultRobotHWSim</robotSimType>
      <legacyModeNS>true</legacyModeNS>
    </plugin>
  </gazebo>

  <!-- Transmission for X-axis -->
  <transmission name="base_to_slider_trans">
    <type>transmission_interface/SimpleTransmission</type>
    <actuator name="motor1">
        <mechanicalReduction>1</mechanicalReduction>
    </actuator>
    <joint name="base_to_slider_joint">
        <hardwareInterface>hardware_interface/PositionJointInterface</hardwareInterface>
    </joint>
  </transmission>

  <!-- Transmission for Y-axis -->
  <transmission name="slider_to_second_trans">
    <type>transmission_interface/SimpleTransmission</type>
    <actuator name="motor2">
        <mechanicalReduction>1</mechanicalReduction>
    </actuator>
    <joint name="slider_to_second_joint">
        <hardwareInterface>hardware_interface/PositionJointInterface</hardwareInterface>
    </joint>
  </transmission>

</robot>